2019-11-27 12:57:18,983 ERROR: Exception on /edit_profile [POST] [in /home/khawar/.local/share/virtualenvs/microblog-7DYM0AUn/lib/python3.6/site-packages/flask/app.py:1891]
Traceback (most recent call last):
  File "/home/khawar/.local/share/virtualenvs/microblog-7DYM0AUn/lib/python3.6/site-packages/sqlalchemy/engine/base.py", line 1246, in _execute_context
    cursor, statement, parameters, context
  File "/home/khawar/.local/share/virtualenvs/microblog-7DYM0AUn/lib/python3.6/site-packages/sqlalchemy/engine/default.py", line 581, in do_execute
    cursor.execute(statement, parameters)
  File "/home/khawar/.local/share/virtualenvs/microblog-7DYM0AUn/lib/python3.6/site-packages/pymysql/cursors.py", line 170, in execute
    result = self._query(query)
  File "/home/khawar/.local/share/virtualenvs/microblog-7DYM0AUn/lib/python3.6/site-packages/pymysql/cursors.py", line 328, in _query
    conn.query(q)
  File "/home/khawar/.local/share/virtualenvs/microblog-7DYM0AUn/lib/python3.6/site-packages/pymysql/connections.py", line 517, in query
    self._affected_rows = self._read_query_result(unbuffered=unbuffered)
  File "/home/khawar/.local/share/virtualenvs/microblog-7DYM0AUn/lib/python3.6/site-packages/pymysql/connections.py", line 732, in _read_query_result
    result.read()
  File "/home/khawar/.local/share/virtualenvs/microblog-7DYM0AUn/lib/python3.6/site-packages/pymysql/connections.py", line 1075, in read
    first_packet = self.connection._read_packet()
  File "/home/khawar/.local/share/virtualenvs/microblog-7DYM0AUn/lib/python3.6/site-packages/pymysql/connections.py", line 684, in _read_packet
    packet.check_error()
  File "/home/khawar/.local/share/virtualenvs/microblog-7DYM0AUn/lib/python3.6/site-packages/pymysql/protocol.py", line 220, in check_error
    err.raise_mysql_exception(self._data)
  File "/home/khawar/.local/share/virtualenvs/microblog-7DYM0AUn/lib/python3.6/site-packages/pymysql/err.py", line 109, in raise_mysql_exception
    raise errorclass(errno, errval)
pymysql.err.IntegrityError: (1062, "Duplicate entry 'bb' for key 'ix_user_username'")

The above exception was the direct cause of the following exception:

Traceback (most recent call last):
  File "/home/khawar/.local/share/virtualenvs/microblog-7DYM0AUn/lib/python3.6/site-packages/flask/app.py", line 2446, in wsgi_app
    response = self.full_dispatch_request()
  File "/home/khawar/.local/share/virtualenvs/microblog-7DYM0AUn/lib/python3.6/site-packages/flask/app.py", line 1951, in full_dispatch_request
    rv = self.handle_user_exception(e)
  File "/home/khawar/.local/share/virtualenvs/microblog-7DYM0AUn/lib/python3.6/site-packages/flask/app.py", line 1820, in handle_user_exception
    reraise(exc_type, exc_value, tb)
  File "/home/khawar/.local/share/virtualenvs/microblog-7DYM0AUn/lib/python3.6/site-packages/flask/_compat.py", line 39, in reraise
    raise value
  File "/home/khawar/.local/share/virtualenvs/microblog-7DYM0AUn/lib/python3.6/site-packages/flask/app.py", line 1949, in full_dispatch_request
    rv = self.dispatch_request()
  File "/home/khawar/.local/share/virtualenvs/microblog-7DYM0AUn/lib/python3.6/site-packages/flask/app.py", line 1935, in dispatch_request
    return self.view_functions[rule.endpoint](**req.view_args)
  File "/home/khawar/.local/share/virtualenvs/microblog-7DYM0AUn/lib/python3.6/site-packages/flask_login/utils.py", line 261, in decorated_view
    return func(*args, **kwargs)
  File "/opt/develop/projects/python/practice/microblog/application/routes.py", line 88, in edit_profile
    db.session.commit()
  File "/home/khawar/.local/share/virtualenvs/microblog-7DYM0AUn/lib/python3.6/site-packages/sqlalchemy/orm/scoping.py", line 162, in do
    return getattr(self.registry(), name)(*args, **kwargs)
  File "/home/khawar/.local/share/virtualenvs/microblog-7DYM0AUn/lib/python3.6/site-packages/sqlalchemy/orm/session.py", line 1027, in commit
    self.transaction.commit()
  File "/home/khawar/.local/share/virtualenvs/microblog-7DYM0AUn/lib/python3.6/site-packages/sqlalchemy/orm/session.py", line 494, in commit
    self._prepare_impl()
  File "/home/khawar/.local/share/virtualenvs/microblog-7DYM0AUn/lib/python3.6/site-packages/sqlalchemy/orm/session.py", line 473, in _prepare_impl
    self.session.flush()
  File "/home/khawar/.local/share/virtualenvs/microblog-7DYM0AUn/lib/python3.6/site-packages/sqlalchemy/orm/session.py", line 2470, in flush
    self._flush(objects)
  File "/home/khawar/.local/share/virtualenvs/microblog-7DYM0AUn/lib/python3.6/site-packages/sqlalchemy/orm/session.py", line 2608, in _flush
    transaction.rollback(_capture_exception=True)
  File "/home/khawar/.local/share/virtualenvs/microblog-7DYM0AUn/lib/python3.6/site-packages/sqlalchemy/util/langhelpers.py", line 68, in __exit__
    compat.reraise(exc_type, exc_value, exc_tb)
  File "/home/khawar/.local/share/virtualenvs/microblog-7DYM0AUn/lib/python3.6/site-packages/sqlalchemy/util/compat.py", line 153, in reraise
    raise value
  File "/home/khawar/.local/share/virtualenvs/microblog-7DYM0AUn/lib/python3.6/site-packages/sqlalchemy/orm/session.py", line 2568, in _flush
    flush_context.execute()
  File "/home/khawar/.local/share/virtualenvs/microblog-7DYM0AUn/lib/python3.6/site-packages/sqlalchemy/orm/unitofwork.py", line 422, in execute
    rec.execute(self)
  File "/home/khawar/.local/share/virtualenvs/microblog-7DYM0AUn/lib/python3.6/site-packages/sqlalchemy/orm/unitofwork.py", line 589, in execute
    uow,
  File "/home/khawar/.local/share/virtualenvs/microblog-7DYM0AUn/lib/python3.6/site-packages/sqlalchemy/orm/persistence.py", line 236, in save_obj
    update,
  File "/home/khawar/.local/share/virtualenvs/microblog-7DYM0AUn/lib/python3.6/site-packages/sqlalchemy/orm/persistence.py", line 996, in _emit_update_statements
    statement, multiparams
  File "/home/khawar/.local/share/virtualenvs/microblog-7DYM0AUn/lib/python3.6/site-packages/sqlalchemy/engine/base.py", line 982, in execute
    return meth(self, multiparams, params)
  File "/home/khawar/.local/share/virtualenvs/microblog-7DYM0AUn/lib/python3.6/site-packages/sqlalchemy/sql/elements.py", line 287, in _execute_on_connection
    return connection._execute_clauseelement(self, multiparams, params)
  File "/home/khawar/.local/share/virtualenvs/microblog-7DYM0AUn/lib/python3.6/site-packages/sqlalchemy/engine/base.py", line 1101, in _execute_clauseelement
    distilled_params,
  File "/home/khawar/.local/share/virtualenvs/microblog-7DYM0AUn/lib/python3.6/site-packages/sqlalchemy/engine/base.py", line 1250, in _execute_context
    e, statement, parameters, cursor, context
  File "/home/khawar/.local/share/virtualenvs/microblog-7DYM0AUn/lib/python3.6/site-packages/sqlalchemy/engine/base.py", line 1476, in _handle_dbapi_exception
    util.raise_from_cause(sqlalchemy_exception, exc_info)
  File "/home/khawar/.local/share/virtualenvs/microblog-7DYM0AUn/lib/python3.6/site-packages/sqlalchemy/util/compat.py", line 398, in raise_from_cause
    reraise(type(exception), exception, tb=exc_tb, cause=cause)
  File "/home/khawar/.local/share/virtualenvs/microblog-7DYM0AUn/lib/python3.6/site-packages/sqlalchemy/util/compat.py", line 152, in reraise
    raise value.with_traceback(tb)
  File "/home/khawar/.local/share/virtualenvs/microblog-7DYM0AUn/lib/python3.6/site-packages/sqlalchemy/engine/base.py", line 1246, in _execute_context
    cursor, statement, parameters, context
  File "/home/khawar/.local/share/virtualenvs/microblog-7DYM0AUn/lib/python3.6/site-packages/sqlalchemy/engine/default.py", line 581, in do_execute
    cursor.execute(statement, parameters)
  File "/home/khawar/.local/share/virtualenvs/microblog-7DYM0AUn/lib/python3.6/site-packages/pymysql/cursors.py", line 170, in execute
    result = self._query(query)
  File "/home/khawar/.local/share/virtualenvs/microblog-7DYM0AUn/lib/python3.6/site-packages/pymysql/cursors.py", line 328, in _query
    conn.query(q)
  File "/home/khawar/.local/share/virtualenvs/microblog-7DYM0AUn/lib/python3.6/site-packages/pymysql/connections.py", line 517, in query
    self._affected_rows = self._read_query_result(unbuffered=unbuffered)
  File "/home/khawar/.local/share/virtualenvs/microblog-7DYM0AUn/lib/python3.6/site-packages/pymysql/connections.py", line 732, in _read_query_result
    result.read()
  File "/home/khawar/.local/share/virtualenvs/microblog-7DYM0AUn/lib/python3.6/site-packages/pymysql/connections.py", line 1075, in read
    first_packet = self.connection._read_packet()
  File "/home/khawar/.local/share/virtualenvs/microblog-7DYM0AUn/lib/python3.6/site-packages/pymysql/connections.py", line 684, in _read_packet
    packet.check_error()
  File "/home/khawar/.local/share/virtualenvs/microblog-7DYM0AUn/lib/python3.6/site-packages/pymysql/protocol.py", line 220, in check_error
    err.raise_mysql_exception(self._data)
  File "/home/khawar/.local/share/virtualenvs/microblog-7DYM0AUn/lib/python3.6/site-packages/pymysql/err.py", line 109, in raise_mysql_exception
    raise errorclass(errno, errval)
sqlalchemy.exc.IntegrityError: (pymysql.err.IntegrityError) (1062, "Duplicate entry 'bb' for key 'ix_user_username'")
[SQL: UPDATE user SET username=%(username)s, about_me=%(about_me)s WHERE user.id = %(user_id)s]
[parameters: {'username': 'bb', 'about_me': 'ccc', 'user_id': 3}]
(Background on this error at: http://sqlalche.me/e/gkpj)
